/opt/conda/bin/python: can't open file '/mnt/DL/Projects/Yolo v8 Gym equipment/notebook/tools/train.py': [Errno 2] No such file or directory
E0812 03:14:38.414000 140447062644544 torch/distributed/elastic/multiprocessing/api.py:826] failed (exitcode: 2) local_rank: 0 (pid: 310716) of binary: /opt/conda/bin/python
Traceback (most recent call last):
  File "/opt/conda/bin/torchrun", line 33, in <module>
    sys.exit(load_entry_point('torch==2.3.1', 'console_scripts', 'torchrun')())
  File "/opt/conda/lib/python3.10/site-packages/torch/distributed/elastic/multiprocessing/errors/__init__.py", line 347, in wrapper
    return f(*args, **kwargs)
  File "/opt/conda/lib/python3.10/site-packages/torch/distributed/run.py", line 879, in main
    run(args)
  File "/opt/conda/lib/python3.10/site-packages/torch/distributed/run.py", line 870, in run
    elastic_launch(
  File "/opt/conda/lib/python3.10/site-packages/torch/distributed/launcher/api.py", line 132, in __call__
    return launch_agent(self._config, self._entrypoint, list(args))
  File "/opt/conda/lib/python3.10/site-packages/torch/distributed/launcher/api.py", line 263, in launch_agent
    raise ChildFailedError(
torch.distributed.elastic.multiprocessing.errors.ChildFailedError: 
============================================================
tools/train.py FAILED
------------------------------------------------------------
Failures:
  <NO_OTHER_FAILURES>
------------------------------------------------------------
Root Cause (first observed failure):
[0]:
  time      : 2024-08-12_03:14:38
  host      : 860f058a9ce6
  rank      : 0 (local_rank: 0)
  exitcode  : 2 (pid: 310716)
  error_file: <N/A>
  traceback : To enable traceback see: https://pytorch.org/docs/stable/elastic/errors.html
============================================================
